2025-05-30 19:31:11 [INFO] logger.py:45 - Logging system initialized
2025-05-30 19:31:11 [INFO] logger.py:46 - Log file: c:\Users\GILIEV\Desktop\Chart generator\App\source\logs\chart_generator_20250530_193111.log
2025-05-30 19:31:11 [INFO] app.py:280 - UI setup complete
2025-05-30 19:31:11 [INFO] app.py:90 - Application initialized
2025-05-30 19:31:20 [ERROR] logger.py:60 - Uncaught exception
Traceback (most recent call last):
  File "c:\Users\GILIEV\Desktop\Chart generator\App\source\ChartGenerator_new.py", line 38, in <module>
    root.destroy()
    ~~~~~~~~~~~~^^
  File "C:\Users\GILIEV\AppData\Local\Programs\Python\Python313\Lib\tkinter\__init__.py", line 2503, in destroy
    self.tk.call('destroy', self._w)
    ~~~~~~~~~~~~^^^^^^^^^^^^^^^^^^^^
_tkinter.TclError: can't invoke "destroy" command: application has been destroyed
